Workbook

Sheet Executive_Summary
B2: Meridian Manufacturing Co. — Inventory Health Executive Summary
B3: 40-SKU catalog | 12 months of sales & inventory history | All figures below are live formulas
B5: Total SKUs Analyzed | E5: SKUs at Stockout Risk | H5: SKUs Overstocked | K5: Excess-Risk SKUs (Overstocked + Erratic)
B6: =COUNTA(Inventory_Planning_Model!A9:A48) -> 40 | E6: =COUNTIF(Inventory_Planning_Model!R9:R48,"Stockout Risk") -> 20 | H6: =COUNTIF(Inventory_Planning_Model!R9:R48,"Overstock") -> 5 | K6: =COUNTIF(Inventory_Planning_Model!V9:V48,"Yes") -> 4
B9: Total Avg. Inventory Value | E9: Value Tied Up in Excess-Risk SKUs | H9: Catalog Inventory Turnover | K9: Forecast Accuracy (WAPE)
B10: =SUM(Inventory_Planning_Model!W9:W48) -> 233844.07 | E10: =SUMIF(Inventory_Planning_Model!V9:V48,"Yes",Inventory_Planning_Model!W9:W48) -> 111068.74 | H10: =SUMPRODUCT(Inventory_Planning_Model!K9:K48,Inventory_Planning_Model!E9:E48)/SUM(Inventory_Planning_Model!W9:W48) -> 7.6970035 | K10: =Forecast_MAPE_Summary!F6 -> 0.28053708
B13: ABC x XYZ Matrix — SKU Count
C15: X (Steady) | D15: Y (Moderate) | E15: Z (Erratic)
B16: A (Top 80% revenue) | C16: =COUNTIFS(ABC_XYZ_Classification!$H$6:$H$45,"A",ABC_XYZ_Classification!$L$6:$L$45,"X") -> 6 | D16: =COUNTIFS(ABC_XYZ_Classification!$H$6:$H$45,"A",ABC_XYZ_Classification!$L$6:$L$45,"Y") -> 5 | E16: =COUNTIFS(ABC_XYZ_Classification!$H$6:$H$45,"A",ABC_XYZ_Classification!$L$6:$L$45,"Z") -> 4
B17: B (Next 15%) | C17: =COUNTIFS(ABC_XYZ_Classification!$H$6:$H$45,"B",ABC_XYZ_Classification!$L$6:$L$45,"X") -> 5 | D17: =COUNTIFS(ABC_XYZ_Classification!$H$6:$H$45,"B",ABC_XYZ_Classification!$L$6:$L$45,"Y") -> 4 | E17: =COUNTIFS(ABC_XYZ_Classification!$H$6:$H$45,"B",ABC_XYZ_Classification!$L$6:$L$45,"Z") -> 1
B18: C (Bottom 5%) | C18: =COUNTIFS(ABC_XYZ_Classification!$H$6:$H$45,"C",ABC_XYZ_Classification!$L$6:$L$45,"X") -> 11 | D18: =COUNTIFS(ABC_XYZ_Classification!$H$6:$H$45,"C",ABC_XYZ_Classification!$L$6:$L$45,"Y") -> 2 | E18: =COUNTIFS(ABC_XYZ_Classification!$H$6:$H$45,"C",ABC_XYZ_Classification!$L$6:$L$45,"Z") -> 2
B20: AZ (top-revenue + erratic-demand) is the highest-attention cell: valuable, unpredictable, and expensive to get wrong either way.
B23: Excess-Risk SKUs (Overstocked + Erratic Demand)
B25: SKU_ID | C25: Description | D25: Category | E25: Days_of_Supply | F25: Lead_Time_Days | G25: Avg_Inventory_Value
B26: =IFERROR(INDEX(Inventory_Planning_Model!$A$9:$A$48,MATCH(1,Inventory_Planning_Model!$X$9:$X$48,0)),"—") -> MM-1033 | C26: =IFERROR(INDEX(Inventory_Planning_Model!$B$9:$B$48,MATCH(1,Inventory_Planning_Model!$X$9:$X$48,0)),"") -> Raw Material Item 04 - Raw Material - Metal Stock | D26: =IFERROR(INDEX(Inventory_Planning_Model!$C$9:$C$48,MATCH(1,Inventory_Planning_Model!$X$9:$X$48,0)),"") -> Raw Material - Metal Stock | E26: =IFERROR(ROUND(INDEX(Inventory_Planning_Model!$P$9:$P$48,MATCH(1,Inventory_Planning_Model!$X$9:$X$48,0)),0),"") -> 71 | F26: =IFERROR(INDEX(Inventory_Planning_Model!$D$9:$D$48,MATCH(1,Inventory_Planning_Model!$X$9:$X$48,0)),"") -> 38 | G26: =IFERROR(ROUND(INDEX(Inventory_Planning_Model!$W$9:$W$48,MATCH(1,Inventory_Planning_Model!$X$9:$X$48,0)),0),"") -> 70522
B27: =IFERROR(INDEX(Inventory_Planning_Model!$A$9:$A$48,MATCH(2,Inventory_Planning_Model!$X$9:$X$48,0)),"—") -> MM-1030 | C27: =IFERROR(INDEX(Inventory_Planning_Model!$B$9:$B$48,MATCH(2,Inventory_Planning_Model!$X$9:$X$48,0)),"") -> Raw Material Item 01 - Raw Material - Metal Stock | D27: =IFERROR(INDEX(Inventory_Planning_Model!$C$9:$C$48,MATCH(2,Inventory_Planning_Model!$X$9:$X$48,0)),"") -> Raw Material - Metal Stock | E27: =IFERROR(ROUND(INDEX(Inventory_Planning_Model!$P$9:$P$48,MATCH(2,Inventory_Planning_Model!$X$9:$X$48,0)),0),"") -> 93 | F27: =IFERROR(INDEX(Inventory_Planning_Model!$D$9:$D$48,MATCH(2,Inventory_Planning_Model!$X$9:$X$48,0)),"") -> 40 | G27: =IFERROR(ROUND(INDEX(Inventory_Planning_Model!$W$9:$W$48,MATCH(2,Inventory_Planning_Model!$X$9:$X$48,0)),0),"") -> 32589
B28: =IFERROR(INDEX(Inventory_Planning_Model!$A$9:$A$48,MATCH(3,Inventory_Planning_Model!$X$9:$X$48,0)),"—") -> MM-1028 | C28: =IFERROR(INDEX(Inventory_Planning_Model!$B$9:$B$48,MATCH(3,Inventory_Planning_Model!$X$9:$X$48,0)),"") -> Pneumatic Components Item 04 - Pneumatic Components | D28: =IFERROR(INDEX(Inventory_Planning_Model!$C$9:$C$48,MATCH(3,Inventory_Planning_Model!$X$9:$X$48,0)),"") -> Pneumatic Components | E28: =IFERROR(ROUND(INDEX(Inventory_Planning_Model!$P$9:$P$48,MATCH(3,Inventory_Planning_Model!$X$9:$X$48,0)),0),"") -> 134 | F28: =IFERROR(INDEX(Inventory_Planning_Model!$D$9:$D$48,MATCH(3,Inventory_Planning_Model!$X$9:$X$48,0)),"") -> 46 | G28: =IFERROR(ROUND(INDEX(Inventory_Planning_Model!$W$9:$W$48,MATCH(3,Inventory_Planning_Model!$X$9:$X$48,0)),0),"") -> 3079
B29: =IFERROR(INDEX(Inventory_Planning_Model!$A$9:$A$48,MATCH(4,Inventory_Planning_Model!$X$9:$X$48,0)),"—") -> MM-1003 | C29: =IFERROR(INDEX(Inventory_Planning_Model!$B$9:$B$48,MATCH(4,Inventory_Planning_Model!$X$9:$X$48,0)),"") -> Fasteners Item 04 - Fasteners & Hardware | D29: =IFERROR(INDEX(Inventory_Planning_Model!$C$9:$C$48,MATCH(4,Inventory_Planning_Model!$X$9:$X$48,0)),"") -> Fasteners & Hardware | E29: =IFERROR(ROUND(INDEX(Inventory_Planning_Model!$P$9:$P$48,MATCH(4,Inventory_Planning_Model!$X$9:$X$48,0)),0),"") -> 351 | F29: =IFERROR(INDEX(Inventory_Planning_Model!$D$9:$D$48,MATCH(4,Inventory_Planning_Model!$X$9:$X$48,0)),"") -> 52 | G29: =IFERROR(ROUND(INDEX(Inventory_Planning_Model!$W$9:$W$48,MATCH(4,Inventory_Planning_Model!$X$9:$X$48,0)),0),"") -> 4879
B30: =IFERROR(INDEX(Inventory_Planning_Model!$A$9:$A$48,MATCH(5,Inventory_Planning_Model!$X$9:$X$48,0)),"—") -> — | C30: =IFERROR(INDEX(Inventory_Planning_Model!$B$9:$B$48,MATCH(5,Inventory_Planning_Model!$X$9:$X$48,0)),"") | D30: =IFERROR(INDEX(Inventory_Planning_Model!$C$9:$C$48,MATCH(5,Inventory_Planning_Model!$X$9:$X$48,0)),"") | E30: =IFERROR(ROUND(INDEX(Inventory_Planning_Model!$P$9:$P$48,MATCH(5,Inventory_Planning_Model!$X$9:$X$48,0)),0),"") | F30: =IFERROR(INDEX(Inventory_Planning_Model!$D$9:$D$48,MATCH(5,Inventory_Planning_Model!$X$9:$X$48,0)),"") | G30: =IFERROR(ROUND(INDEX(Inventory_Planning_Model!$W$9:$W$48,MATCH(5,Inventory_Planning_Model!$X$9:$X$48,0)),0),"")
B31: =IFERROR(INDEX(Inventory_Planning_Model!$A$9:$A$48,MATCH(6,Inventory_Planning_Model!$X$9:$X$48,0)),"—") -> — | C31: =IFERROR(INDEX(Inventory_Planning_Model!$B$9:$B$48,MATCH(6,Inventory_Planning_Model!$X$9:$X$48,0)),"") | D31: =IFERROR(INDEX(Inventory_Planning_Model!$C$9:$C$48,MATCH(6,Inventory_Planning_Model!$X$9:$X$48,0)),"") | E31: =IFERROR(ROUND(INDEX(Inventory_Planning_Model!$P$9:$P$48,MATCH(6,Inventory_Planning_Model!$X$9:$X$48,0)),0),"") | F31: =IFERROR(INDEX(Inventory_Planning_Model!$D$9:$D$48,MATCH(6,Inventory_Planning_Model!$X$9:$X$48,0)),"") | G31: =IFERROR(ROUND(INDEX(Inventory_Planning_Model!$W$9:$W$48,MATCH(6,Inventory_Planning_Model!$X$9:$X$48,0)),0),"")
B32: =IFERROR(INDEX(Inventory_Planning_Model!$A$9:$A$48,MATCH(7,Inventory_Planning_Model!$X$9:$X$48,0)),"—") -> — | C32: =IFERROR(INDEX(Inventory_Planning_Model!$B$9:$B$48,MATCH(7,Inventory_Planning_Model!$X$9:$X$48,0)),"") | D32: =IFERROR(INDEX(Inventory_Planning_Model!$C$9:$C$48,MATCH(7,Inventory_Planning_Model!$X$9:$X$48,0)),"") | E32: =IFERROR(ROUND(INDEX(Inventory_Planning_Model!$P$9:$P$48,MATCH(7,Inventory_Planning_Model!$X$9:$X$48,0)),0),"") | F32: =IFERROR(INDEX(Inventory_Planning_Model!$D$9:$D$48,MATCH(7,Inventory_Planning_Model!$X$9:$X$48,0)),"") | G32: =IFERROR(ROUND(INDEX(Inventory_Planning_Model!$W$9:$W$48,MATCH(7,Inventory_Planning_Model!$X$9:$X$48,0)),0),"")
B33: =IFERROR(INDEX(Inventory_Planning_Model!$A$9:$A$48,MATCH(8,Inventory_Planning_Model!$X$9:$X$48,0)),"—") -> — | C33: =IFERROR(INDEX(Inventory_Planning_Model!$B$9:$B$48,MATCH(8,Inventory_Planning_Model!$X$9:$X$48,0)),"") | D33: =IFERROR(INDEX(Inventory_Planning_Model!$C$9:$C$48,MATCH(8,Inventory_Planning_Model!$X$9:$X$48,0)),"") | E33: =IFERROR(ROUND(INDEX(Inventory_Planning_Model!$P$9:$P$48,MATCH(8,Inventory_Planning_Model!$X$9:$X$48,0)),0),"") | F33: =IFERROR(INDEX(Inventory_Planning_Model!$D$9:$D$48,MATCH(8,Inventory_Planning_Model!$X$9:$X$48,0)),"") | G33: =IFERROR(ROUND(INDEX(Inventory_Planning_Model!$W$9:$W$48,MATCH(8,Inventory_Planning_Model!$X$9:$X$48,0)),0),"")
B36: Source: simulated NetSuite-style export, Meridian Manufacturing Co. | Model built in Excel with live formulas | See README tab for methodology & assumptions.

Sheet README
B2: Meridian Manufacturing Co. — Demand Forecasting & Inventory Balancing Model
B3: Supply Chain Analytics Portfolio — Project 2
B6: What this workbook does
C7: Turns a simulated 12-month NetSuite-style sales/inventory export (40 SKUs) into a live
C8: replenishment planning model: ABC/XYZ classification, safety stock & reorder points, EOQ,
C9: a FORECAST.LINEAR demand baseline with a measured MAPE, and a red/yellow/green inventory
C10: health flag for every SKU.
B12: Tab guide
B13: Assumptions | C13: Every hardcoded input used anywhere in this model, in one place.
B14: Data_Quality_Log | C14: What was messy in the raw export and how it was cleaned before this workbook.
B15: Raw_SKU_Master | C15: 40-SKU catalog: category, supplier, cost, price, UOM, lead time.
B16: Raw_Sales_Weekly | C16: 1,805 rows of cleaned weekly sell-through, one row per SKU per week.
B17: Raw_Inventory_Monthly | C17: 480 rows of month-end on-hand / on-order snapshots.
B18: ABC_XYZ_Classification | C18: Revenue-based ABC tier x demand-variability XYZ tier for every SKU.
B19: Inventory_Planning_Model | C19: Safety stock, reorder point, EOQ, and stockout/overstock status — all live formulas.
B20: Forecast_Detail | C20: Week-by-week forecast-vs-actual for the 6-week holdout, 36 eligible SKUs.
B21: Forecast_MAPE_Summary | C21: Forecast accuracy (MAPE) by SKU, plus the catalog-wide average.
B22: Executive_Summary | C22: The one-page view: KPI cards, ABC/XYZ matrix, and the SKUs that matter most.
B24: Color key
B25: Blue text | C25: Hardcoded input or assumption
B26: Black text | C26: Formula (same sheet)
B27: Green text | C27: Formula linking to another sheet
B28: Red / Yellow / Green fill | C28: Stockout risk / Overstock / Healthy (Inventory_Planning_Model tab)

Sheet Assumptions
B2: Model Assumptions
B3: Every hardcoded number used in a formula elsewhere in this workbook is defined here, once.
B5: Name | C5: Value | D5: Cell | E5: Used for | F5: Rationale
B6: Service_Level_Z | C6: 1.65 | D6: C6 | E6: Safety stock | F6: Z-score for a 95% single-tail service level (industry-standard planning target).
B7: Order_Cost_S | C7: 75 | D7: C7 | E7: EOQ | F7: Assumed fixed cost per purchase order ($): PO processing + receiving labor.
B8: Holding_Cost_Rate | C8: 0.22 | D8: C8 | E8: EOQ | F8: Annual carrying cost as % of unit cost (typical industrial range: 18-30%).
B9: MOQ_Lot_Size | C9: 25 | D9: C9 | E9: Order rounding | F9: Assumed minimum order lot size (units) enforced via ROUNDUP across the catalog.
B10: Forecast_Holdout_Weeks | C10: 6 | D10: C10 | E10: MAPE test | F10: Most recent 6 weeks per SKU held out and forecast from the prior weeks to measure accuracy.
B11: Min_Weeks_For_Forecast | C11: 15 | D11: C11 | E11: MAPE eligibility | F11: SKUs with fewer weeks of history are excluded from statistical forecasting (too new/sparse).
B12: ABC_A_Cutoff | C12: 0.8 | D12: C12 | E12: ABC class | F12: SKUs contributing to the top 80% of cumulative revenue -> Class A.
B13: ABC_B_Cutoff | C13: 0.95 | D13: C13 | E13: ABC class | F13: Next slice, 80-95% cumulative revenue -> Class B. Remainder -> Class C.
B14: XYZ_X_Cutoff | C14: 0.3 | D14: C14 | E14: XYZ class | F14: Coefficient of variation <= 0.30 -> steady demand (X).
B15: XYZ_Y_Cutoff | C15: 0.55 | D15: C15 | E15: XYZ class | F15: CV 0.30-0.55 -> moderate variability (Y). Above 0.55 -> erratic (Z).
B16: Stockout_Multiple | C16: 1 | D16: C16 | E16: Inventory status | F16: Days of supply (incl. pipeline) < 1x lead time -> Stockout Risk.
B17: Overstock_Multiple | C17: 3 | D17: C17 | E17: Inventory status | F17: Days of supply (incl. pipeline) > 3x lead time -> Overstock.
B18: Weeks_Per_Year | C18: 52 | D18: C18 | E18: Annualization | F18: Used to annualize weekly demand into EOQ's D term.

Sheet Data_Quality_Log
B2: Data Quality Log — Raw NetSuite Export
B3: Issues found in the raw export and how each was resolved before building this workbook.
B5: Issue | C5: Where found | D5: Raw example | E5: Resolution
B6: Mixed date formats | C6: Sales export, Order_Date | D6: 01/18/2026, 2026-01-18, 18-Jan-2026, 01/18/26 | E6: Parsed all 4 formats to ISO dates in Python/SQL before loading; 0 unparseable after cleaning.
B7: Duplicate transaction rows | C7: Sales export | D7: 27 exact-duplicate rows (~1.5% of file) | E7: Dropped via SQL DISTINCT on SKU + date + qty + revenue + warehouse.
B8: UOM inconsistency | C8: SKU master & inventory snapshot | D8: EA / Each / each / ea. | PCS / pcs / Pcs | E8: Standardized to 4 canonical codes (EA, PCS, BOX, FT) via a lookup table.
B9: Supplier name casing | C9: SKU master | D9: Midwest Fastener Co. / MIDWEST FASTENER CO. / midwest fastener co. | E9: Standardized to title case.
B10: Missing On_Order_Qty | C10: Inventory snapshot | D10: 46 of 480 rows (9.6%) blank | E10: Treated as 0 (no open PO) with a flag column retained so the gap stays visible, not hidden.
B11: Sparse / new-SKU history | C11: Sales export | D11: 4 SKUs with <15 weeks of recorded sales | E11: Excluded from statistical forecasting (Forecast_MAPE_Summary); flagged for judgmental forecasting instead.

Sheet Raw_SKU_Master
A1: SKU_ID | B1: SKU_Description | C1: Category | D1: Supplier (cleaned) | E1: Unit_Cost | F1: Unit_Price | G1: UOM (raw) | H1: UOM (clean) | I1: Lead_Time_Days | J1: Warehouse
A2: MM-1000 | B2: Fasteners Item 01 - Fasteners & Hardware | C2: Fasteners & Hardware | D2: Midwest Fastener Co. | E2: 3.82 | F2: 6.94 | G2: PCS | H2: PCS | I2: 65 | J2: WH-OHIO
A3: MM-1001 | B3: Fasteners Item 02 - Fasteners & Hardware | C3: Fasteners & Hardware | D3: Midwest Fastener Co. | E3: 3.86 | F3: 6.59 | G3: EA | H3: EA | I3: 43 | J3: WH-NEVADA
A4: MM-1002 | B4: Fasteners Item 03 - Fasteners & Hardware | C4: Fasteners & Hardware | D4: Midwest Fastener Co. | E4: 2.83 | F4: 4.93 | G4: ea. | H4: EA | I4: 60 | J4: WH-NEVADA
A5: MM-1003 | B5: Fasteners Item 04 - Fasteners & Hardware | C5: Fasteners & Hardware | D5: Midwest Fastener Co. | E5: 2.56 | F5: 5.13 | G5: box | H5: BOX | I5: 52 | J5: WH-OHIO
A6: MM-1004 | B6: Fasteners Item 05 - Fasteners & Hardware | C6: Fasteners & Hardware | D6: Midwest Fastener Co. | E6: 3.55 | F6: 6.83 | G6: EA | H6: EA | I6: 49 | J6: WH-OHIO
A7: MM-1005 | B7: Bearings Item 01 - Bearings & Bushings | C7: Bearings & Bushings | D7: Precision Bearing Supply | E7: 3.02 | F7: 4.89 | G7: pcs | H7: PCS | I7: 95 | J7: WH-OHIO
A8: MM-1006 | B8: Bearings Item 02 - Bearings & Bushings | C8: Bearings & Bushings | D8: Precision Bearing Supply | E8: 3.9 | F8: 6.75 | G8: ea. | H8: EA | I8: 126 | J8: WH-TEXAS
A9: MM-1007 | B9: Bearings Item 03 - Bearings & Bushings | C9: Bearings & Bushings | D9: Precision Bearing Supply | E9: 3.36 | F9: 4.96 | G9: pcs | H9: PCS | I9: 128 | J9: WH-TEXAS
A10: MM-1008 | B10: Bearings Item 04 - Bearings & Bushings | C10: Bearings & Bushings | D10: Precision Bearing Supply | E10: 5.13 | F10: 7.78 | G10: pcs | H10: PCS | I10: 164 | J10: WH-OHIO
A11: MM-1009 | B11: Bearings Item 05 - Bearings & Bushings | C11: Bearings & Bushings | D11: Precision Bearing Supply | E11: 5.45 | F11: 8.96 | G11: each | H11: EA | I11: 141 | J11: WH-OHIO
A12: MM-1010 | B12: Electric Motors Item 01 - Electric Motors & Drives | C12: Electric Motors & Drives | D12: Torque Dynamics Llc | E12: 13.08 | F12: 27.85 | G12: ea. | H12: EA | I12: 32 | J12: WH-TEXAS
A13: MM-1011 | B13: Electric Motors Item 02 - Electric Motors & Drives | C13: Electric Motors & Drives | D13: Torque Dynamics Llc | E13: 15.22 | F13: 32.01 | G13: Each | H13: EA | I13: 52 | J13: WH-NEVADA
... A41: MM-1039 | B41: Packaging Materials Item 05 - Packaging Materials | C41: Packaging Materials | D41: Securepack Solutions | E41: 0.96 | F41: 2.38 | G41: Each | H41: EA | I41: 16 | J41: WH-NEVADA

Sheet Raw_Sales_Weekly
A1: SKU_ID | B1: Week_Ending | C1: Qty_Sold | D1: Revenue | E1: Week_Index
A2: MM-1000 | B2: 2025-07-13 | C2: 142 | D2: 961.93 | E2: 1
A3: MM-1000 | B3: 2025-07-20 | C3: 184 | D3: 1242.63 | E3: 2
A4: MM-1000 | B4: 2025-07-27 | C4: 159 | D4: 1076.92 | E4: 3
A5: MM-1000 | B5: 2025-08-03 | C5: 181 | D5: 1286.49 | E5: 4
A6: MM-1000 | B6: 2025-08-10 | C6: 96 | D6: 678.31 | E6: 5
A7: MM-1000 | B7: 2025-08-17 | C7: 157 | D7: 1098.89 | E7: 6
A8: MM-1000 | B8: 2025-08-24 | C8: 133 | D8: 902.78 | E8: 7
A9: MM-1000 | B9: 2025-08-31 | C9: 135 | D9: 937.7 | E9: 8
A10: MM-1000 | B10: 2025-09-07 | C10: 208 | D10: 1440.3 | E10: 9
A11: MM-1000 | B11: 2025-09-14 | C11: 132 | D11: 923.75 | E11: 10
A12: MM-1000 | B12: 2025-09-21 | C12: 152 | D12: 1032.08 | E12: 11
A13: MM-1000 | B13: 2025-09-28 | C13: 64 | D13: 441.95 | E13: 12
... A1806: MM-1039 | B1806: 2026-07-05 | C1806: 115 | D1806: 271.78 | E1806: 52

Sheet Raw_Inventory_Monthly
A1: SKU_ID | B1: Month | C1: On_Hand_Qty | D1: On_Order_Qty | E1: UOM | F1: Warehouse | G1: On_Order_Qty_Filled
A2: MM-1000 | B2: 2025-08 | C2: 331 | D2: 117 | E2: PCS | F2: WH-OHIO | G2: =IF(D2="",0,D2) -> 117
A3: MM-1000 | B3: 2025-09 | C3: 392 | D3: 118 | E3: pcs | F3: WH-OHIO | G3: =IF(D3="",0,D3) -> 118
A4: MM-1000 | B4: 2025-10 | C4: 324 | D4: 19 | E4: pcs | F4: WH-OHIO | G4: =IF(D4="",0,D4) -> 19
A5: MM-1000 | B5: 2025-11 | C5: 380 | D5: 75 | E5: pcs | F5: WH-OHIO | G5: =IF(D5="",0,D5) -> 75
A6: MM-1000 | B6: 2025-12 | C6: 499 | D6: 5 | E6: Pcs | F6: WH-OHIO | G6: =IF(D6="",0,D6) -> 5
A7: MM-1000 | B7: 2026-01 | C7: 471 | D7: 259 | E7: PCS | F7: WH-OHIO | G7: =IF(D7="",0,D7) -> 259
A8: MM-1000 | B8: 2026-02 | C8: 404 | D8: 150 | E8: Pcs | F8: WH-OHIO | G8: =IF(D8="",0,D8) -> 150
A9: MM-1000 | B9: 2026-03 | C9: 595 | D9: 242 | E9: PCS | F9: WH-OHIO | G9: =IF(D9="",0,D9) -> 242
A10: MM-1000 | B10: 2026-04 | C10: 516 | D10: 247 | E10: Pcs | F10: WH-OHIO | G10: =IF(D10="",0,D10) -> 247
A11: MM-1000 | B11: 2026-05 | C11: 351 | D11: 19 | E11: Pcs | F11: WH-OHIO | G11: =IF(D11="",0,D11) -> 19
A12: MM-1000 | B12: 2026-06 | C12: 0 | D12: 149 | E12: pcs | F12: WH-OHIO | G12: =IF(D12="",0,D12) -> 149
A13: MM-1000 | B13: 2026-07 | C13: 400 | D13: 32 | E13: PCS | F13: WH-OHIO | G13: =IF(D13="",0,D13) -> 32
... A15: MM-1001 | B15: 2025-09 | C15: 0 | D15: 240 | E15: ea. | F15: WH-NEVADA | G15: =IF(D15="",0,D15) -> 240
A16: MM-1001 | B16: 2025-10 | C16: 0 | E16: ea. | F16: WH-NEVADA | G16: =IF(D16="",0,D16) -> 0
A17: MM-1001 | B17: 2025-11 | C17: 334 | D17: 115 | E17: EA | F17: WH-NEVADA | G17: =IF(D17="",0,D17) -> 115
A18: MM-1001 | B18: 2025-12 | C18: 0 | D18: 60 | E18: Each | F18: WH-NEVADA | G18: =IF(D18="",0,D18) -> 60
A19: MM-1001 | B19: 2026-01 | C19: 302 | D19: 220 | E19: Each | F19: WH-NEVADA | G19: =IF(D19="",0,D19) -> 220
A20: MM-1001 | B20: 2026-02 | C20: 0 | D20: 49 | E20: EA | F20: WH-NEVADA | G20: =IF(D20="",0,D20) -> 49
A21: MM-1001 | B21: 2026-03 | C21: 0 | D21: 194 | E21: ea. | F21: WH-NEVADA | G21: =IF(D21="",0,D21) -> 194
A22: MM-1001 | B22: 2026-04 | C22: 347 | D22: 11 | E22: EA | F22: WH-NEVADA | G22: =IF(D22="",0,D22) -> 11
A23: MM-1001 | B23: 2026-05 | C23: 473 | E23: each | F23: WH-NEVADA | G23: =IF(D23="",0,D23) -> 0
A24: MM-1001 | B24: 2026-06 | C24: 496 | D24: 211 | E24: EA | F24: WH-NEVADA | G24: =IF(D24="",0,D24) -> 211
A25: MM-1001 | B25: 2026-07 | C25: 486 | D25: 164 | E25: each | F25: WH-NEVADA | G25: =IF(D25="",0,D25) -> 164
A26: MM-1002 | B26: 2025-08 | C26: 384 | D26: 200 | E26: each | F26: WH-NEVADA | G26: =IF(D26="",0,D26) -> 200
A27: MM-1002 | B27: 2025-09 | C27: 426 | D27: 133 | E27: EA | F27: WH-NEVADA | G27: =IF(D27="",0,D27) -> 133
A28: MM-1002 | B28: 2025-10 | C28: 0 | E28: ea. | F28: WH-NEVADA | G28: =IF(D28="",0,D28) -> 0
A29: MM-1002 | B29: 2025-11 | C29: 687 | D29: 240 | E29: each | F29: WH-NEVADA | G29: =IF(D29="",0,D29) -> 240
A30: MM-1002 | B30: 2025-12 | C30: 642 | D30: 128 | E30: ea. | F30: WH-NEVADA | G30: =IF(D30="",0,D30) -> 128
A31: MM-1002 | B31: 2026-01 | C31: 641 | D31: 189 | E31: each | F31: WH-NEVADA | G31: =IF(D31="",0,D31) -> 189
A32: MM-1002 | B32: 2026-02 | C32: 638 | D32: 53 | E32: ea. | F32: WH-NEVADA | G32: =IF(D32="",0,D32) -> 53
A33: MM-1002 | B33: 2026-03 | C33: 0 | D33: 214 | E33: ea. | F33: WH-NEVADA | G33: =IF(D33="",0,D33) -> 214
A34: MM-1002 | B34: 2026-04 | C34: 380 | D34: 154 | E34: Each | F34: WH-NEVADA | G34: =IF(D34="",0,D34) -> 154
A35: MM-1002 | B35: 2026-05 | C35: 667 | D35: 227 | E35: ea. | F35: WH-NEVADA | G35: =IF(D35="",0,D35) -> 227
A36: MM-1002 | B36: 2026-06 | C36: 573 | E36: EA | F36: WH-NEVADA | G36: =IF(D36="",0,D36) -> 0
A37: MM-1002 | B37: 2026-07 | C37: 0 | E37: ea. | F37: WH-NEVADA | G37: =IF(D37="",0,D37) -> 0
A38: MM-1003 | B38: 2025-08 | C38: 1841 | D38: 162 | E38: each | F38: WH-OHIO | G38: =IF(D38="",0,D38) -> 162
A39: MM-1003 | B39: 2025-09 | C39: 1872 | D39: 303 | E39: Each | F39: WH-OHIO | G39: =IF(D39="",0,D39) -> 303
A40: MM-1003 | B40: 2025-10 | C40: 0 | D40: 168 | E40: Each | F40: WH-OHIO | G40: =IF(D40="",0,D40) -> 168
A41: MM-1003 | B41: 2025-11 | C41: 2406 | D41: 158 | E41: ea. | F41: WH-OHIO | G41: =IF(D41="",0,D41) -> 158
...

Sheet ABC_XYZ_Classification
B2: ABC (Revenue) x XYZ (Demand Variability) Classification
B3: Sorted by revenue, descending. Every value is a live formula against Raw_Sales_Weekly / Raw_SKU_Master.
A5: SKU_ID | B5: SKU_Description | C5: Category | D5: Total_Revenue | E5: Total_Qty_Sold | F5: Cum_Revenue | G5: Cum_Pct | H5: ABC_Class | I5: Mean_Weekly_Qty | J5: StDev_Weekly_Qty | K5: CV | L5: XYZ_Class | M5: ABC_XYZ
A6: MM-1033 | B6: =INDEX(Raw_SKU_Master!$B$2:$B$41,MATCH(A6,Raw_SKU_Master!$A$2:$A$41,0)) -> Raw Material Item 04 - Raw Material - Metal Stock | C6: =INDEX(Raw_SKU_Master!$C$2:$C$41,MATCH(A6,Raw_SKU_Master!$A$2:$A$41,0)) -> Raw Material - Metal Stock | D6: =SUMIF(Raw_Sales_Weekly!$A$2:$A$1806,A6,Raw_Sales_Weekly!$D$2:$D$1806) -> 544456.12 | E6: =SUMIF(Raw_Sales_Weekly!$A$2:$A$1806,A6,Raw_Sales_Weekly!$C$2:$C$1806) -> 10524 | F6: =SUM($D$6:D6) -> 544456.12 | G6: =F6/SUM($D$6:$D$45) -> 0.17212532 | H6: =IF(G6<=Assumptions!$C$12,"A",IF(G6<=Assumptions!$C$13,"B","C")) -> A | I6: =AVERAGEIF(Raw_Sales_Weekly!$A$2:$A$1806,A6,Raw_Sales_Weekly!$C$2:$C$1806) -> 210.48 | J6: =SQRT(SUMPRODUCT((Raw_Sales_Weekly!$A$2:$A$1806=A6)*(Raw_Sales_Weekly!$C$2:$C$1806-I6)^2)/COUNTIF(Raw_Sales_Weekly!$A$2:$A$1806,A6)) -> 121.64214 | K6: =IFERROR(J6/I6,0) -> 0.5779273 | L6: =IF(K6<=Assumptions!$C$14,"X",IF(K6<=Assumptions!$C$15,"Y","Z")) -> Z | M6: =H6&L6 -> AZ
A7: MM-1032 | B7: =INDEX(Raw_SKU_Master!$B$2:$B$41,MATCH(A7,Raw_SKU_Master!$A$2:$A$41,0)) -> Raw Material Item 03 - Raw Material - Metal Stock | C7: =INDEX(Raw_SKU_Master!$C$2:$C$41,MATCH(A7,Raw_SKU_Master!$A$2:$A$41,0)) -> Raw Material - Metal Stock | D7: =SUMIF(Raw_Sales_Weekly!$A$2:$A$1806,A7,Raw_Sales_Weekly!$D$2:$D$1806) -> 303904.71 | E7: =SUMIF(Raw_Sales_Weekly!$A$2:$A$1806,A7,Raw_Sales_Weekly!$C$2:$C$1806) -> 8252 | F7: =SUM($D$6:D7) -> 848360.83 | G7: =F7/SUM($D$6:$D$45) -> 0.26820229 | H7: =IF(G7<=Assumptions!$C$12,"A",IF(G7<=Assumptions!$C$13,"B","C")) -> A | I7: =AVERAGEIF(Raw_Sales_Weekly!$A$2:$A$1806,A7,Raw_Sales_Weekly!$C$2:$C$1806) -> 161.80392 | J7: =SQRT(SUMPRODUCT((Raw_Sales_Weekly!$A$2:$A$1806=A7)*(Raw_Sales_Weekly!$C$2:$C$1806-I7)^2)/COUNTIF(Raw_Sales_Weekly!$A$2:$A$1806,A7)) -> 93.090093 | K7: =IFERROR(J7/I7,0) -> 0.57532656 | L7: =IF(K7<=Assumptions!$C$14,"X",IF(K7<=Assumptions!$C$15,"Y","Z")) -> Z | M7: =H7&L7 -> AZ
A8: MM-1025 | B8: =INDEX(Raw_SKU_Master!$B$2:$B$41,MATCH(A8,Raw_SKU_Master!$A$2:$A$41,0)) -> Pneumatic Components Item 01 - Pneumatic Components | C8: =INDEX(Raw_SKU_Master!$C$2:$C$41,MATCH(A8,Raw_SKU_Master!$A$2:$A$41,0)) -> Pneumatic Components | D8: =SUMIF(Raw_Sales_Weekly!$A$2:$A$1806,A8,Raw_Sales_Weekly!$D$2:$D$1806) -> 239857.28 | E8: =SUMIF(Raw_Sales_Weekly!$A$2:$A$1806,A8,Raw_Sales_Weekly!$C$2:$C$1806) -> 8260 | F8: =SUM($D$6:D8) -> 1088218.1 | G8: =F8/SUM($D$6:$D$45) -> 0.3440312 | H8: =IF(G8<=Assumptions!$C$12,"A",IF(G8<=Assumptions!$C$13,"B","C")) -> A | I8: =AVERAGEIF(Raw_Sales_Weekly!$A$2:$A$1806,A8,Raw_Sales_Weekly!$C$2:$C$1806) -> 165.2 | J8: =SQRT(SUMPRODUCT((Raw_Sales_Weekly!$A$2:$A$1806=A8)*(Raw_Sales_Weekly!$C$2:$C$1806-I8)^2)/COUNTIF(Raw_Sales_Weekly!$A$2:$A$1806,A8)) -> 80.431089 | K8: =IFERROR(J8/I8,0) -> 0.486871 | L8: =IF(K8<=Assumptions!$C$14,"X",IF(K8<=Assumptions!$C$15,"Y","Z")) -> Y | M8: =H8&L8 -> AY
A9: MM-1030 | B9: =INDEX(Raw_SKU_Master!$B$2:$B$41,MATCH(A9,Raw_SKU_Master!$A$2:$A$41,0)) -> Raw Material Item 01 - Raw Material - Metal Stock | C9: =INDEX(Raw_SKU_Master!$C$2:$C$41,MATCH(A9,Raw_SKU_Master!$A$2:$A$41,0)) -> Raw Material - Metal Stock | D9: =SUMIF(Raw_Sales_Weekly!$A$2:$A$1806,A9,Raw_Sales_Weekly!$D$2:$D$1806) -> 187809.68 | E9: =SUMIF(Raw_Sales_Weekly!$A$2:$A$1806,A9,Raw_Sales_Weekly!$C$2:$C$1806) -> 4081 | F9: =SUM($D$6:D9) -> 1276027.8 | G9: =F9/SUM($D$6:$D$45) -> 0.40340568 | H9: =IF(G9<=Assumptions!$C$12,"A",IF(G9<=Assumptions!$C$13,"B","C")) -> A | I9: =AVERAGEIF(Raw_Sales_Weekly!$A$2:$A$1806,A9,Raw_Sales_Weekly!$C$2:$C$1806) -> 80.019608 | J9: =SQRT(SUMPRODUCT((Raw_Sales_Weekly!$A$2:$A$1806=A9)*(Raw_Sales_Weekly!$C$2:$C$1806-I9)^2)/COUNTIF(Raw_Sales_Weekly!$A$2:$A$1806,A9)) -> 50.206823 | K9: =IFERROR(J9/I9,0) -> 0.62743151 | L9: =IF(K9<=Assumptions!$C$14,"X",IF(K9<=Assumptions!$C$15,"Y","Z")) -> Z | M9: =H9&L9 -> AZ
A10: MM-1014 | B10: =INDEX(Raw_SKU_Master!$B$2:$B$41,MATCH(A10,Raw_SKU_Master!$A$2:$A$41,0)) -> Electric Motors Item 05 - Electric Motors & Drives | C10: =INDEX(Raw_SKU_Master!$C$2:$C$41,MATCH(A10,Raw_SKU_Master!$A$2:$A$41,0)) -> Electric Motors & Drives | D10: =SUMIF(Raw_Sales_Weekly!$A$2:$A$1806,A10,Raw_Sales_Weekly!$D$2:$D$1806) -> 156097.75 | E10: =SUMIF(Raw_Sales_Weekly!$A$2:$A$1806,A10,Raw_Sales_Weekly!$C$2:$C$1806) -> 3722 | F10: =SUM($D$6:D10) -> 1432125.5 | G10: =F10/SUM($D$6:$D$45) -> 0.4527547 | H10: =IF(G10<=Assumptions!$C$12,"A",IF(G10<=Assumptions!$C$13,"B","C")) -> A | I10: =AVERAGEIF(Raw_Sales_Weekly!$A$2:$A$1806,A10,Raw_Sales_Weekly!$C$2:$C$1806) -> 71.576923 | J10: =SQRT(SUMPRODUCT((Raw_Sales_Weekly!$A$2:$A$1806=A10)*(Raw_Sales_Weekly!$C$2:$C$1806-I10)^2)/COUNTIF(Raw_Sales_Weekly!$A$2:$A$1806,A10)) -> 10.508872 | K10: =IFERROR(J10/I10,0) -> 0.14681928 | L10: =IF(K10<=Assumptions!$C$14,"X",IF(K10<=Assumptions!$C$15,"Y","Z")) -> X | M10: =H10&L10 -> AX
A11: MM-1010 | B11: =INDEX(Raw_SKU_Master!$B$2:$B$41,MATCH(A11,Raw_SKU_Master!$A$2:$A$41,0)) -> Electric Motors Item 01 - Electric Motors & Drives | C11: =INDEX(Raw_SKU_Master!$C$2:$C$41,MATCH(A11,Raw_SKU_Master!$A$2:$A$41,0)) -> Electric Motors & Drives | D11: =SUMIF(Raw_Sales_Weekly!$A$2:$A$1806,A11,Raw_Sales_Weekly!$D$2:$D$1806) -> 142199.48 | E11: =SUMIF(Raw_Sales_Weekly!$A$2:$A$1806,A11,Raw_Sales_Weekly!$C$2:$C$1806) -> 5128 | F11: =SUM($D$6:D11) -> 1574325 | G11: =F11/SUM($D$6:$D$45) -> 0.4977099 | H11: =IF(G11<=Assumptions!$C$12,"A",IF(G11<=Assumptions!$C$13,"B","C")) -> A | I11: =AVERAGEIF(Raw_Sales_Weekly!$A$2:$A$1806,A11,Raw_Sales_Weekly!$C$2:$C$1806) -> 98.615385 | J11: =SQRT(SUMPRODUCT((Raw_Sales_Weekly!$A$2:$A$1806=A11)*(Raw_Sales_Weekly!$C$2:$C$1806-I11)^2)/COUNTIF(Raw_Sales_Weekly!$A$2:$A$1806,A11)) -> 13.147322 | K11: =IFERROR(J11/I11,0) -> 0.13331918 | L11: =IF(K11<=Assumptions!$C$14,"X",IF(K11<=Assumptions!$C$15,"Y","Z")) -> X | M11: =H11&L11 -> AX
A12: MM-1011 | B12: =INDEX(Raw_SKU_Master!$B$2:$B$41,MATCH(A12,Raw_SKU_Master!$A$2:$A$41,0)) -> Electric Motors Item 02 - Electric Motors & Drives | C12: =INDEX(Raw_SKU_Master!$C$2:$C$41,MATCH(A12,Raw_SKU_Master!$A$2:$A$41,0)) -> Electric Motors & Drives | D12: =SUMIF(Raw_Sales_Weekly!$A$2:$A$1806,A12,Raw_Sales_Weekly!$D$2:$D$1806) -> 140581.06 | E12: =SUMIF(Raw_Sales_Weekly!$A$2:$A$1806,A12,Raw_Sales_Weekly!$C$2:$C$1806) -> 4406 | F12: =SUM($D$6:D12) -> 1714906.1 | G12: =F12/SUM($D$6:$D$45) -> 0.54215344 | H12: =IF(G12<=Assumptions!$C$12,"A",IF(G12<=Assumptions!$C$13,"B","C")) -> A | I12: =AVERAGEIF(Raw_Sales_Weekly!$A$2:$A$1806,A12,Raw_Sales_Weekly!$C$2:$C$1806) -> 209.80952 | J12: =SQRT(SUMPRODUCT((Raw_Sales_Weekly!$A$2:$A$1806=A12)*(Raw_Sales_Weekly!$C$2:$C$1806-I12)^2)/COUNTIF(Raw_Sales_Weekly!$A$2:$A$1806,A12)) -> 30.562378 | K12: =IFERROR(J12/I12,0) -> 0.14566726 | L12: =IF(K12<=Assumptions!$C$14,"X",IF(K12<=Assumptions!$C$15,"Y","Z")) -> X | M12: =H12&L12 -> AX
A13: MM-1013 | B13: =INDEX(Raw_SKU_Master!$B$2:$B$41,MATCH(A13,Raw_SKU_Master!$A$2:$A$41,0)) -> Electric Motors Item 04 - Electric Motors & Drives | C13: =INDEX(Raw_SKU_Master!$C$2:$C$41,MATCH(A13,Raw_SKU_Master!$A$2:$A$41,0)) -> Electric Motors & Drives | D13: =SUMIF(Raw_Sales_Weekly!$A$2:$A$1806,A13,Raw_Sales_Weekly!$D$2:$D$1806) -> 140269.93 | E13: =SUMIF(Raw_Sales_Weekly!$A$2:$A$1806,A13,Raw_Sales_Weekly!$C$2:$C$1806) -> 5749 | F13: =SUM($D$6:D13) -> 1855176 | G13: =F13/SUM($D$6:$D$45) -> 0.58649863 | H13: =IF(G13<=Assumptions!$C$12,"A",IF(G13<=Assumptions!$C$13,"B","C")) -> A | I13: =AVERAGEIF(Raw_Sales_Weekly!$A$2:$A$1806,A13,Raw_Sales_Weekly!$C$2:$C$1806) -> 110.55769 | J13: =SQRT(SUMPRODUCT((Raw_Sales_Weekly!$A$2:$A$1806=A13)*(Raw_Sales_Weekly!$C$2:$C$1806-I13)^2)/COUNTIF(Raw_Sales_Weekly!$A$2:$A$1806,A13)) -> 15.501133 | K13: =IFERROR(J13/I13,0) -> 0.14020855 | L13: =IF(K13<=Assumptions!$C$14,"X",IF(K13<=Assumptions!$C$15,"Y","Z")) -> X | M13: =H13&L13 -> AX
A14: MM-1015 | B14: =INDEX(Raw_SKU_Master!$B$2:$B$41,MATCH(A14,Raw_SKU_Master!$A$2:$A$41,0)) -> Sensors Item 01 - Sensors & Controls | C14: =INDEX(Raw_SKU_Master!$C$2:$C$41,MATCH(A14,Raw_SKU_Master!$A$2:$A$41,0)) -> Sensors & Controls | D14: =SUMIF(Raw_Sales_Weekly!$A$2:$A$1806,A14,Raw_Sales_Weekly!$D$2:$D$1806) -> 108623.95 | E14: =SUMIF(Raw_Sales_Weekly!$A$2:$A$1806,A14,Raw_Sales_Weekly!$C$2:$C$1806) -> 9605 | F14: =SUM($D$6:D14) -> 1963800 | G14: =F14/SUM($D$6:$D$45) -> 0.6208392 | H14: =IF(G14<=Assumptions!$C$12,"A",IF(G14<=Assumptions!$C$13,"B","C")) -> A | I14: =AVERAGEIF(Raw_Sales_Weekly!$A$2:$A$1806,A14,Raw_Sales_Weekly!$C$2:$C$1806) -> 184.71154 | J14: =SQRT(SUMPRODUCT((Raw_Sales_Weekly!$A$2:$A$1806=A14)*(Raw_Sales_Weekly!$C$2:$C$1806-I14)^2)/COUNTIF(Raw_Sales_Weekly!$A$2:$A$1806,A14)) -> 110.24297 | K14: =IFERROR(J14/I14,0) -> 0.59683858 | L14: =IF(K14<=Assumptions!$C$14,"X",IF(K14<=Assumptions!$C$15,"Y","Z")) -> Z | M14: =H14&L14 -> AZ
A15: MM-1019 | B15: =INDEX(Raw_SKU_Master!$B$2:$B$41,MATCH(A15,Raw_SKU_Master!$A$2:$A$41,0)) -> Sensors Item 05 - Sensors & Controls | C15: =INDEX(Raw_SKU_Master!$C$2:$C$41,MATCH(A15,Raw_SKU_Master!$A$2:$A$41,0)) -> Sensors & Controls | D15: =SUMIF(Raw_Sales_Weekly!$A$2:$A$1806,A15,Raw_Sales_Weekly!$D$2:$D$1806) -> 107028.35 | E15: =SUMIF(Raw_Sales_Weekly!$A$2:$A$1806,A15,Raw_Sales_Weekly!$C$2:$C$1806) -> 11884 | F15: =SUM($D$6:D15) -> 2070828.3 | G15: =F15/SUM($D$6:$D$45) -> 0.65467533 | H15: =IF(G15<=Assumptions!$C$12,"A",IF(G15<=Assumptions!$C$13,"B","C")) -> A | I15: =AVERAGEIF(Raw_Sales_Weekly!$A$2:$A$1806,A15,Raw_Sales_Weekly!$C$2:$C$1806) -> 228.53846 | J15: =SQRT(SUMPRODUCT((Raw_Sales_Weekly!$A$2:$A$1806=A15)*(Raw_Sales_Weekly!$C$2:$C$1806-I15)^2)/COUNTIF(Raw_Sales_Weekly!$A$2:$A$1806,A15)) -> 72.072736 | K15: =IFERROR(J15/I15,0) -> 0.31536371 | L15: =IF(K15<=Assumptions!$C$14,"X",IF(K15<=Assumptions!$C$15,"Y","Z")) -> Y | M15: =H15&L15 -> AY
A16: MM-1034 | B16: =INDEX(Raw_SKU_Master!$B$2:$B$41,MATCH(A16,Raw_SKU_Master!$A$2:$A$41,0)) -> Raw Material Item 05 - Raw Material - Metal Stock | C16: =INDEX(Raw_SKU_Master!$C$2:$C$41,MATCH(A16,Raw_SKU_Master!$A$2:$A$41,0)) -> Raw Material - Metal Stock | D16: =SUMIF(Raw_Sales_Weekly!$A$2:$A$1806,A16,Raw_Sales_Weekly!$D$2:$D$1806) -> 99301.07 | E16: =SUMIF(Raw_Sales_Weekly!$A$2:$A$1806,A16,Raw_Sales_Weekly!$C$2:$C$1806) -> 2368 | F16: =SUM($D$6:D16) -> 2170129.4 | G16: =F16/SUM($D$6:$D$45) -> 0.68606854 | H16: =IF(G16<=Assumptions!$C$12,"A",IF(G16<=Assumptions!$C$13,"B","C")) -> A | I16: =AVERAGEIF(Raw_Sales_Weekly!$A$2:$A$1806,A16,Raw_Sales_Weekly!$C$2:$C$1806) -> 45.538462 | J16: =SQRT(SUMPRODUCT((Raw_Sales_Weekly!$A$2:$A$1806=A16)*(Raw_Sales_Weekly!$C$2:$C$1806-I16)^2)/COUNTIF(Raw_Sales_Weekly!$A$2:$A$1806,A16)) -> 6.3198757 | K16: =IFERROR(J16/I16,0) -> 0.13878105 | L16: =IF(K16<=Assumptions!$C$14,"X",IF(K16<=Assumptions!$C$15,"Y","Z")) -> X | M16: =H16&L16 -> AX
A17: MM-1018 | B17: =INDEX(Raw_SKU_Master!$B$2:$B$41,MATCH(A17,Raw_SKU_Master!$A$2:$A$41,0)) -> Sensors Item 04 - Sensors & Controls | C17: =INDEX(Raw_SKU_Master!$C$2:$C$41,MATCH(A17,Raw_SKU_Master!$A$2:$A$41,0)) -> Sensors & Controls | D17: =SUMIF(Raw_Sales_Weekly!$A$2:$A$1806,A17,Raw_Sales_Weekly!$D$2:$D$1806) -> 91339.24 | E17: =SUMIF(Raw_Sales_Weekly!$A$2:$A$1806,A17,Raw_Sales_Weekly!$C$2:$C$1806) -> 9392 | F17: =SUM($D$6:D17) -> 2261468.6 | G17: =F17/SUM($D$6:$D$45) -> 0.71494469 | H17: =IF(G17<=Assumptions!$C$12,"A",IF(G17<=Assumptions!$C$13,"B","C")) -> A | I17: =AVERAGEIF(Raw_Sales_Weekly!$A$2:$A$1806,A17,Raw_Sales_Weekly!$C$2:$C$1806) -> 180.61538 | J17: =SQRT(SUMPRODUCT((Raw_Sales_Weekly!$A$2:$A$1806=A17)*(Raw_Sales_Weekly!$C$2:$C$1806-I17)^2)/COUNTIF(Raw_Sales_Weekly!$A$2:$A$1806,A17)) -> 55.467299 | K17: =IFERROR(J17/I17,0) -> 0.30710174 | L17: =IF(K17<=Assumptions!$C$14,"X",IF(K17<=Assumptions!$C$15,"Y","Z")) -> Y | M17: =H17&L17 -> AY
... A45: MM-1037 | B45: =INDEX(Raw_SKU_Master!$B$2:$B$41,MATCH(A45,Raw_SKU_Master!$A$2:$A$41,0)) -> Packaging Materials Item 03 - Packaging Materials | C45: =INDEX(Raw_SKU_Master!$C$2:$C$41,MATCH(A45,Raw_SKU_Master!$A$2:$A$41,0)) -> Packaging Materials | D45: =SUMIF(Raw_Sales_Weekly!$A$2:$A$1806,A45,Raw_Sales_Weekly!$D$2:$D$1806) -> 1966.29 | E45: =SUMIF(Raw_Sales_Weekly!$A$2:$A$1806,A45,Raw_Sales_Weekly!$C$2:$C$1806) -> 1169 | F45: =SUM($D$6:D45) -> 3163137.9 | G45: =F45/SUM($D$6:$D$45) -> 1 | H45: =IF(G45<=Assumptions!$C$12,"A",IF(G45<=Assumptions!$C$13,"B","C")) -> C | I45: =AVERAGEIF(Raw_Sales_Weekly!$A$2:$A$1806,A45,Raw_Sales_Weekly!$C$2:$C$1806) -> 89.923077 | J45: =SQRT(SUMPRODUCT((Raw_Sales_Weekly!$A$2:$A$1806=A45)*(Raw_Sales_Weekly!$C$2:$C$1806-I45)^2)/COUNTIF(Raw_Sales_Weekly!$A$2:$A$1806,A45)) -> 7.7604673 | K45: =IFERROR(J45/I45,0) -> 0.086301176 | L45: =IF(K45<=Assumptions!$C$14,"X",IF(K45<=Assumptions!$C$15,"Y","Z")) -> X | M45: =H45&L45 -> CX

Sheet Inventory_Planning_Model
B2: Inventory Planning Model
B3: Safety stock, reorder point, EOQ, and next-period forecast -- every cell is a live formula.
B5: Excess-Risk Days-of-Supply Threshold (75th pctile, floor 60 days): | F5: =MAX(60,PERCENTILE(P9:P48,0.75)) -> 60
A8: SKU_ID | B8: SKU_Description | C8: Category | D8: Lead_Time_Days | E8: Unit_Cost | F8: Avg_Daily_Usage | G8: StDev_Weekly_Qty | H8: Lead_Time_Weeks | I8: Safety_Stock | J8: Reorder_Point | K8: Annual_Demand_Qty | L8: EOQ | M8: EOQ_Rounded_to_MOQ | N8: Avg_On_Hand_Qty | O8: Avg_On_Order_Qty | P8: Days_of_Supply | Q8: Days_of_Supply_Incl_Pipeline | R8: Inventory_Status | S8: Next_Period_Forecast_Qty | T8: XYZ_Class | U8: ABC_Class | V8: Excess_Risk_SKU | W8: Avg_Inventory_Value | X8: Excess_Risk_Rank
A9: MM-1033 | B9: =ABC_XYZ_Classification!B6 -> Raw Material Item 04 - Raw Material - Metal Stock | C9: =ABC_XYZ_Classification!C6 -> Raw Material - Metal Stock | D9: =INDEX(Raw_SKU_Master!$I$2:$I$41,MATCH(A9,Raw_SKU_Master!$A$2:$A$41,0)) -> 38 | E9: =INDEX(Raw_SKU_Master!$E$2:$E$41,MATCH(A9,Raw_SKU_Master!$A$2:$A$41,0)) -> 34.39 | F9: =ABC_XYZ_Classification!E6/(Assumptions!$C$18*7) -> 28.912088 | G9: =ABC_XYZ_Classification!J6 -> 121.64214 | H9: =D9/7 -> 5.4285714 | I9: =ROUNDUP(Assumptions!$C$6*G9*SQRT(H9),0) -> 468 | J9: =ROUNDUP(F9*D9+I9,0) -> 1567 | K9: =ABC_XYZ_Classification!E6 -> 10524 | L9: =ROUND(SQRT((2*K9*Assumptions!$C$7)/(E9*Assumptions!$C$8)),0) -> 457 | M9: =ROUNDUP(L9/Assumptions!$C$9,0)*Assumptions!$C$9 -> 475 | N9: =AVERAGEIF(Raw_Inventory_Monthly!$A$2:$A$481,A9,Raw_Inventory_Monthly!$C$2:$C$481) -> 2050.6667 | O9: =AVERAGEIF(Raw_Inventory_Monthly!$A$2:$A$481,A9,Raw_Inventory_Monthly!$G$2:$G$481) -> 194.5 | P9: =IFERROR(N9/F9,0) -> 70.927657 | Q9: =IFERROR((N9+O9)/F9,0) -> 77.654947 | R9: =IF(Q9<Assumptions!$C$16*D9,"Stockout Risk",IF(Q9>Assumptions!$C$17*D9,"Overstock","Healthy")) -> Healthy | S9: =ROUND(FORECAST(MAX(Raw_Sales_Weekly!$E$1484:$E$1533)+1,Raw_Sales_Weekly!$C$1484:$C$1533,Raw_Sales_Weekly!$E$1484:$E$1533),0) -> 185 | T9: =ABC_XYZ_Classification!L6 -> Z | U9: =ABC_XYZ_Classification!H6 -> A | V9: =IF(AND(P9>$F$5,T9="Z"),"Yes","No") -> Yes | W9: =N9*E9 -> 70522.427 | X9: =IF(V9="Yes",COUNTIF($V$9:V9,"Yes"),"") -> 1
A10: MM-1032 | B10: =ABC_XYZ_Classification!B7 -> Raw Material Item 03 - Raw Material - Metal Stock | C10: =ABC_XYZ_Classification!C7 -> Raw Material - Metal Stock | D10: =INDEX(Raw_SKU_Master!$I$2:$I$41,MATCH(A10,Raw_SKU_Master!$A$2:$A$41,0)) -> 43 | E10: =INDEX(Raw_SKU_Master!$E$2:$E$41,MATCH(A10,Raw_SKU_Master!$A$2:$A$41,0)) -> 25.32 | F10: =ABC_XYZ_Classification!E7/(Assumptions!$C$18*7) -> 22.67033 | G10: =ABC_XYZ_Classification!J7 -> 93.090093 | H10: =D10/7 -> 6.1428571 | I10: =ROUNDUP(Assumptions!$C$6*G10*SQRT(H10),0) -> 381 | J10: =ROUNDUP(F10*D10+I10,0) -> 1356 | K10: =ABC_XYZ_Classification!E7 -> 8252 | L10: =ROUND(SQRT((2*K10*Assumptions!$C$7)/(E10*Assumptions!$C$8)),0) -> 471 | M10: =ROUNDUP(L10/Assumptions!$C$9,0)*Assumptions!$C$9 -> 475 | N10: =AVERAGEIF(Raw_Inventory_Monthly!$A$2:$A$481,A10,Raw_Inventory_Monthly!$C$2:$C$481) -> 474.25 | O10: =AVERAGEIF(Raw_Inventory_Monthly!$A$2:$A$481,A10,Raw_Inventory_Monthly!$G$2:$G$481) -> 185.25 | P10: =IFERROR(N10/F10,0) -> 20.919413 | Q10: =IFERROR((N10+O10)/F10,0) -> 29.090887 | R10: =IF(Q10<Assumptions!$C$16*D10,"Stockout Risk",IF(Q10>Assumptions!$C$17*D10,"Overstock","Healthy")) -> Stockout Risk | S10: =ROUND(FORECAST(MAX(Raw_Sales_Weekly!$E$1433:$E$1483)+1,Raw_Sales_Weekly!$C$1433:$C$1483,Raw_Sales_Weekly!$E$1433:$E$1483),0) -> 152 | T10: =ABC_XYZ_Classification!L7 -> Z | U10: =ABC_XYZ_Classification!H7 -> A | V10: =IF(AND(P10>$F$5,T10="Z"),"Yes","No") -> No | W10: =N10*E10 -> 12008.01 | X10: =IF(V10="Yes",COUNTIF($V$9:V10,"Yes"),"")
A11: MM-1025 | B11: =ABC_XYZ_Classification!B8 -> Pneumatic Components Item 01 - Pneumatic Components | C11: =ABC_XYZ_Classification!C8 -> Pneumatic Components | D11: =INDEX(Raw_SKU_Master!$I$2:$I$41,MATCH(A11,Raw_SKU_Master!$A$2:$A$41,0)) -> 55 | E11: =INDEX(Raw_SKU_Master!$E$2:$E$41,MATCH(A11,Raw_SKU_Master!$A$2:$A$41,0)) -> 14.33 | F11: =ABC_XYZ_Classification!E8/(Assumptions!$C$18*7) -> 22.692308 | G11: =ABC_XYZ_Classification!J8 -> 80.431089 | H11: =D11/7 -> 7.8571429 | I11: =ROUNDUP(Assumptions!$C$6*G11*SQRT(H11),0) -> 372 | J11: =ROUNDUP(F11*D11+I11,0) -> 1621 | K11: =ABC_XYZ_Classification!E8 -> 8260 | L11: =ROUND(SQRT((2*K11*Assumptions!$C$7)/(E11*Assumptions!$C$8)),0) -> 627 | M11: =ROUNDUP(L11/Assumptions!$C$9,0)*Assumptions!$C$9 -> 650 | N11: =AVERAGEIF(Raw_Inventory_Monthly!$A$2:$A$481,A11,Raw_Inventory_Monthly!$C$2:$C$481) -> 1192.5833 | O11: =AVERAGEIF(Raw_Inventory_Monthly!$A$2:$A$481,A11,Raw_Inventory_Monthly!$G$2:$G$481) -> 114 | P11: =IFERROR(N11/F11,0) -> 52.55452 | Q11: =IFERROR((N11+O11)/F11,0) -> 57.578249 | R11: =IF(Q11<Assumptions!$C$16*D11,"Stockout Risk",IF(Q11>Assumptions!$C$17*D11,"Overstock","Healthy")) -> Healthy | S11: =ROUND(FORECAST(MAX(Raw_Sales_Weekly!$E$1152:$E$1201)+1,Raw_Sales_Weekly!$C$1152:$C$1201,Raw_Sales_Weekly!$E$1152:$E$1201),0) -> 136 | T11: =ABC_XYZ_Classification!L8 -> Y | U11: =ABC_XYZ_Classification!H8 -> A | V11: =IF(AND(P11>$F$5,T11="Z"),"Yes","No") -> No | W11: =N11*E11 -> 17089.719 | X11: =IF(V11="Yes",COUNTIF($V$9:V11,"Yes"),"")
A12: MM-1030 | B12: =ABC_XYZ_Classification!B9 -> Raw Material Item 01 - Raw Material - Metal Stock | C12: =ABC_XYZ_Classification!C9 -> Raw Material - Metal Stock | D12: =INDEX(Raw_SKU_Master!$I$2:$I$41,MATCH(A12,Raw_SKU_Master!$A$2:$A$41,0)) -> 40 | E12: =INDEX(Raw_SKU_Master!$E$2:$E$41,MATCH(A12,Raw_SKU_Master!$A$2:$A$41,0)) -> 31.3 | F12: =ABC_XYZ_Classification!E9/(Assumptions!$C$18*7) -> 11.211538 | G12: =ABC_XYZ_Classification!J9 -> 50.206823 | H12: =D12/7 -> 5.7142857 | I12: =ROUNDUP(Assumptions!$C$6*G12*SQRT(H12),0) -> 199 | J12: =ROUNDUP(F12*D12+I12,0) -> 648 | K12: =ABC_XYZ_Classification!E9 -> 4081 | L12: =ROUND(SQRT((2*K12*Assumptions!$C$7)/(E12*Assumptions!$C$8)),0) -> 298 | M12: =ROUNDUP(L12/Assumptions!$C$9,0)*Assumptions!$C$9 -> 300 | N12: =AVERAGEIF(Raw_Inventory_Monthly!$A$2:$A$481,A12,Raw_Inventory_Monthly!$C$2:$C$481) -> 1041.1667 | O12: =AVERAGEIF(Raw_Inventory_Monthly!$A$2:$A$481,A12,Raw_Inventory_Monthly!$G$2:$G$481) -> 75.333333 | P12: =IFERROR(N12/F12,0) -> 92.865638 | Q12: =IFERROR((N12+O12)/F12,0) -> 99.584906 | R12: =IF(Q12<Assumptions!$C$16*D12,"Stockout Risk",IF(Q12>Assumptions!$C$17*D12,"Overstock","Healthy")) -> Healthy | S12: =ROUND(FORECAST(MAX(Raw_Sales_Weekly!$E$1377:$E$1427)+1,Raw_Sales_Weekly!$C$1377:$C$1427,Raw_Sales_Weekly!$E$1377:$E$1427),0) -> 100 | T12: =ABC_XYZ_Classification!L9 -> Z | U12: =ABC_XYZ_Classification!H9 -> A | V12: =IF(AND(P12>$F$5,T12="Z"),"Yes","No") -> Yes | W12: =N12*E12 -> 32588.517 | X12: =IF(V12="Yes",COUNTIF($V$9:V12,"Yes"),"") -> 2
A13: MM-1014 | B13: =ABC_XYZ_Classification!B10 -> Electric Motors Item 05 - Electric Motors & Drives | C13: =ABC_XYZ_Classification!C10 -> Electric Motors & Drives | D13: =INDEX(Raw_SKU_Master!$I$2:$I$41,MATCH(A13,Raw_SKU_Master!$A$2:$A$41,0)) -> 40 | E13: =INDEX(Raw_SKU_Master!$E$2:$E$41,MATCH(A13,Raw_SKU_Master!$A$2:$A$41,0)) -> 20.28 | F13: =ABC_XYZ_Classification!E10/(Assumptions!$C$18*7) -> 10.225275 | G13: =ABC_XYZ_Classification!J10 -> 10.508872 | H13: =D13/7 -> 5.7142857 | I13: =ROUNDUP(Assumptions!$C$6*G13*SQRT(H13),0) -> 42 | J13: =ROUNDUP(F13*D13+I13,0) -> 452 | K13: =ABC_XYZ_Classification!E10 -> 3722 | L13: =ROUND(SQRT((2*K13*Assumptions!$C$7)/(E13*Assumptions!$C$8)),0) -> 354 | M13: =ROUNDUP(L13/Assumptions!$C$9,0)*Assumptions!$C$9 -> 375 | N13: =AVERAGEIF(Raw_Inventory_Monthly!$A$2:$A$481,A13,Raw_Inventory_Monthly!$C$2:$C$481) -> 277.83333 | O13: =AVERAGEIF(Raw_Inventory_Monthly!$A$2:$A$481,A13,Raw_Inventory_Monthly!$G$2:$G$481) -> 75.166667 | P13: =IFERROR(N13/F13,0) -> 27.171234 | Q13: =IFERROR((N13+O13)/F13,0) -> 34.5223 | R13: =IF(Q13<Assumptions!$C$16*D13,"Stockout Risk",IF(Q13>Assumptions!$C$17*D13,"Overstock","Healthy")) -> Stockout Risk | S13: =ROUND(FORECAST(MAX(Raw_Sales_Weekly!$E$615:$E$666)+1,Raw_Sales_Weekly!$C$615:$C$666,Raw_Sales_Weekly!$E$615:$E$666),0) -> 68 | T13: =ABC_XYZ_Classification!L10 -> X | U13: =ABC_XYZ_Classification!H10 -> A | V13: =IF(AND(P13>$F$5,T13="Z"),"Yes","No") -> No | W13: =N13*E13 -> 5634.46 | X13: =IF(V13="Yes",COUNTIF($V$9:V13,"Yes"),"")
A14: MM-1010 | B14: =ABC_XYZ_Classification!B11 -> Electric Motors Item 01 - Electric Motors & Drives | C14: =ABC_XYZ_Classification!C11 -> Electric Motors & Drives | D14: =INDEX(Raw_SKU_Master!$I$2:$I$41,MATCH(A14,Raw_SKU_Master!$A$2:$A$41,0)) -> 32 | E14: =INDEX(Raw_SKU_Master!$E$2:$E$41,MATCH(A14,Raw_SKU_Master!$A$2:$A$41,0)) -> 13.08 | F14: =ABC_XYZ_Classification!E11/(Assumptions!$C$18*7) -> 14.087912 | G14: =ABC_XYZ_Classification!J11 -> 13.147322 | H14: =D14/7 -> 4.5714286 | I14: =ROUNDUP(Assumptions!$C$6*G14*SQRT(H14),0) -> 47 | J14: =ROUNDUP(F14*D14+I14,0) -> 498 | K14: =ABC_XYZ_Classification!E11 -> 5128 | L14: =ROUND(SQRT((2*K14*Assumptions!$C$7)/(E14*Assumptions!$C$8)),0) -> 517 | M14: =ROUNDUP(L14/Assumptions!$C$9,0)*Assumptions!$C$9 -> 525 | N14: =AVERAGEIF(Raw_Inventory_Monthly!$A$2:$A$481,A14,Raw_Inventory_Monthly!$C$2:$C$481) -> 317.08333 | O14: =AVERAGEIF(Raw_Inventory_Monthly!$A$2:$A$481,A14,Raw_Inventory_Monthly!$G$2:$G$481) -> 91.25 | P14: =IFERROR(N14/F14,0) -> 22.507475 | Q14: =IFERROR((N14+O14)/F14,0) -> 28.984659 | R14: =IF(Q14<Assumptions!$C$16*D14,"Stockout Risk",IF(Q14>Assumptions!$C$17*D14,"Overstock","Healthy")) -> Stockout Risk | S14: =ROUND(FORECAST(MAX(Raw_Sales_Weekly!$E$440:$E$491)+1,Raw_Sales_Weekly!$C$440:$C$491,Raw_Sales_Weekly!$E$440:$E$491),0) -> 99 | T14: =ABC_XYZ_Classification!L11 -> X | U14: =ABC_XYZ_Classification!H11 -> A | V14: =IF(AND(P14>$F$5,T14="Z"),"Yes","No") -> No | W14: =N14*E14 -> 4147.45 | X14: =IF(V14="Yes",COUNTIF($V$9:V14,"Yes"),"")
A15: MM-1011 | B15: =ABC_XYZ_Classification!B12 -> Electric Motors Item 02 - Electric Motors & Drives | C15: =ABC_XYZ_Classification!C12 -> Electric Motors & Drives | D15: =INDEX(Raw_SKU_Master!$I$2:$I$41,MATCH(A15,Raw_SKU_Master!$A$2:$A$41,0)) -> 52 | E15: =INDEX(Raw_SKU_Master!$E$2:$E$41,MATCH(A15,Raw_SKU_Master!$A$2:$A$41,0)) -> 15.22 | F15: =ABC_XYZ_Classification!E12/(Assumptions!$C$18*7) -> 12.104396 | G15: =ABC_XYZ_Classification!J12 -> 30.562378 | H15: =D15/7 -> 7.4285714 | I15: =ROUNDUP(Assumptions!$C$6*G15*SQRT(H15),0) -> 138 | J15: =ROUNDUP(F15*D15+I15,0) -> 768 | K15: =ABC_XYZ_Classification!E12 -> 4406 | L15: =ROUND(SQRT((2*K15*Assumptions!$C$7)/(E15*Assumptions!$C$8)),0) -> 444 | M15: =ROUNDUP(L15/Assumptions!$C$9,0)*Assumptions!$C$9 -> 450 | N15: =AVERAGEIF(Raw_Inventory_Monthly!$A$2:$A$481,A15,Raw_Inventory_Monthly!$C$2:$C$481) -> 851.41667 | O15: =AVERAGEIF(Raw_Inventory_Monthly!$A$2:$A$481,A15,Raw_Inventory_Monthly!$G$2:$G$481) -> 157.58333 | P15: =IFERROR(N15/F15,0) -> 70.339461 | Q15: =IFERROR((N15+O15)/F15,0) -> 83.358148 | R15: =IF(Q15<Assumptions!$C$16*D15,"Stockout Risk",IF(Q15>Assumptions!$C$17*D15,"Overstock","Healthy")) -> Healthy | S15: =ROUND(FORECAST(MAX(Raw_Sales_Weekly!$E$492:$E$512)+1,Raw_Sales_Weekly!$C$492:$C$512,Raw_Sales_Weekly!$E$492:$E$512),0) -> 200 | T15: =ABC_XYZ_Classification!L12 -> X | U15: =ABC_XYZ_Classification!H12 -> A | V15: =IF(AND(P15>$F$5,T15="Z"),"Yes","No") -> No | W15: =N15*E15 -> 12958.562 | X15: =IF(V15="Yes",COUNTIF($V$9:V15,"Yes"),"")
A16: MM-1013 | B16: =ABC_XYZ_Classification!B13 -> Electric Motors Item 04 - Electric Motors & Drives | C16: =ABC_XYZ_Classification!C13 -> Electric Motors & Drives | D16: =INDEX(Raw_SKU_Master!$I$2:$I$41,MATCH(A16,Raw_SKU_Master!$A$2:$A$41,0)) -> 44 | E16: =INDEX(Raw_SKU_Master!$E$2:$E$41,MATCH(A16,Raw_SKU_Master!$A$2:$A$41,0)) -> 12.69 | F16: =ABC_XYZ_Classification!E13/(Assumptions!$C$18*7) -> 15.793956 | G16: =ABC_XYZ_Classification!J13 -> 15.501133 | H16: =D16/7 -> 6.2857143 | I16: =ROUNDUP(Assumptions!$C$6*G16*SQRT(H16),0) -> 65 | J16: =ROUNDUP(F16*D16+I16,0) -> 760 | K16: =ABC_XYZ_Classification!E13 -> 5749 | L16: =ROUND(SQRT((2*K16*Assumptions!$C$7)/(E16*Assumptions!$C$8)),0) -> 556 | M16: =ROUNDUP(L16/Assumptions!$C$9,0)*Assumptions!$C$9 -> 575 | N16: =AVERAGEIF(Raw_Inventory_Monthly!$A$2:$A$481,A16,Raw_Inventory_Monthly!$C$2:$C$481) -> 345.33333 | O16: =AVERAGEIF(Raw_Inventory_Monthly!$A$2:$A$481,A16,Raw_Inventory_Monthly!$G$2:$G$481) -> 62.666667 | P16: =IFERROR(N16/F16,0) -> 21.864904 | Q16: =IFERROR((N16+O16)/F16,0) -> 25.832667 | R16: =IF(Q16<Assumptions!$C$16*D16,"Stockout Risk",IF(Q16>Assumptions!$C$17*D16,"Overstock","Healthy")) -> Stockout Risk | S16: =ROUND(FORECAST(MAX(Raw_Sales_Weekly!$E$563:$E$614)+1,Raw_Sales_Weekly!$C$563:$C$614,Raw_Sales_Weekly!$E$563:$E$614),0) -> 108 | T16: =ABC_XYZ_Classification!L13 -> X | U16: =ABC_XYZ_Classification!H13 -> A | V16: =IF(AND(P16>$F$5,T16="Z"),"Yes","No") -> No | W16: =N16*E16 -> 4382.28 | X16: =IF(V16="Yes",COUNTIF($V$9:V16,"Yes"),"")
A17: MM-1015 | B17: =ABC_XYZ_Classification!B14 -> Sensors Item 01 - Sensors & Controls | C17: =ABC_XYZ_Classification!C14 -> Sensors & Controls | D17: =INDEX(Raw_SKU_Master!$I$2:$I$41,MATCH(A17,Raw_SKU_Master!$A$2:$A$41,0)) -> 27 | E17: =INDEX(Raw_SKU_Master!$E$2:$E$41,MATCH(A17,Raw_SKU_Master!$A$2:$A$41,0)) -> 5.56 | F17: =ABC_XYZ_Classification!E14/(Assumptions!$C$18*7) -> 26.387363 | G17: =ABC_XYZ_Classification!J14 -> 110.24297 | H17: =D17/7 -> 3.8571429 | I17: =ROUNDUP(Assumptions!$C$6*G17*SQRT(H17),0) -> 358 | J17: =ROUNDUP(F17*D17+I17,0) -> 1071 | K17: =ABC_XYZ_Classification!E14 -> 9605 | L17: =ROUND(SQRT((2*K17*Assumptions!$C$7)/(E17*Assumptions!$C$8)),0) -> 1085 | M17: =ROUNDUP(L17/Assumptions!$C$9,0)*Assumptions!$C$9 -> 1100 | N17: =AVERAGEIF(Raw_Inventory_Monthly!$A$2:$A$481,A17,Raw_Inventory_Monthly!$C$2:$C$481) -> 1398.8333 | O17: =AVERAGEIF(Raw_Inventory_Monthly!$A$2:$A$481,A17,Raw_Inventory_Monthly!$G$2:$G$481) -> 154.66667 | P17: =IFERROR(N17/F17,0) -> 53.011487 | Q17: =IFERROR((N17+O17)/F17,0) -> 58.872879 | R17: =IF(Q17<Assumptions!$C$16*D17,"Stockout Risk",IF(Q17>Assumptions!$C$17*D17,"Overstock","Healthy")) -> Healthy | S17: =ROUND(FORECAST(MAX(Raw_Sales_Weekly!$E$667:$E$718)+1,Raw_Sales_Weekly!$C$667:$C$718,Raw_Sales_Weekly!$E$667:$E$718),0) -> 146 | T17: =ABC_XYZ_Classification!L14 -> Z | U17: =ABC_XYZ_Classification!H14 -> A | V17: =IF(AND(P17>$F$5,T17="Z"),"Yes","No") -> No | W17: =N17*E17 -> 7777.5133 | X17: =IF(V17="Yes",COUNTIF($V$9:V17,"Yes"),"")
A18: MM-1019 | B18: =ABC_XYZ_Classification!B15 -> Sensors Item 05 - Sensors & Controls | C18: =ABC_XYZ_Classification!C15 -> Sensors & Controls | D18: =INDEX(Raw_SKU_Master!$I$2:$I$41,MATCH(A18,Raw_SKU_Master!$A$2:$A$41,0)) -> 22 | E18: =INDEX(Raw_SKU_Master!$E$2:$E$41,MATCH(A18,Raw_SKU_Master!$A$2:$A$41,0)) -> 3.76 | F18: =ABC_XYZ_Classification!E15/(Assumptions!$C$18*7) -> 32.648352 | G18: =ABC_XYZ_Classification!J15 -> 72.072736 | H18: =D18/7 -> 3.1428571 | I18: =ROUNDUP(Assumptions!$C$6*G18*SQRT(H18),0) -> 211 | J18: =ROUNDUP(F18*D18+I18,0) -> 930 | K18: =ABC_XYZ_Classification!E15 -> 11884 | L18: =ROUND(SQRT((2*K18*Assumptions!$C$7)/(E18*Assumptions!$C$8)),0) -> 1468 | M18: =ROUNDUP(L18/Assumptions!$C$9,0)*Assumptions!$C$9 -> 1475 | N18: =AVERAGEIF(Raw_Inventory_Monthly!$A$2:$A$481,A18,Raw_Inventory_Monthly!$C$2:$C$481) -> 1682.5 | O18: =AVERAGEIF(Raw_Inventory_Monthly!$A$2:$A$481,A18,Raw_Inventory_Monthly!$G$2:$G$481) -> 156.66667 | P18: =IFERROR(N18/F18,0) -> 51.533995 | Q18: =IFERROR((N18+O18)/F18,0) -> 56.332604 | R18: =IF(Q18<Assumptions!$C$16*D18,"Stockout Risk",IF(Q18>Assumptions!$C$17*D18,"Overstock","Healthy")) -> Healthy | S18: =ROUND(FORECAST(MAX(Raw_Sales_Weekly!$E$840:$E$891)+1,Raw_Sales_Weekly!$C$840:$C$891,Raw_Sales_Weekly!$E$840:$E$891),0) -> 271 | T18: =ABC_XYZ_Classification!L15 -> Y | U18: =ABC_XYZ_Classification!H15 -> A | V18: =IF(AND(P18>$F$5,T18="Z"),"Yes","No") -> No | W18: =N18*E18 -> 6326.2 | X18: =IF(V18="Yes",COUNTIF($V$9:V18,"Yes"),"")
A19: MM-1034 | B19: =ABC_XYZ_Classification!B16 -> Raw Material Item 05 - Raw Material - Metal Stock | C19: =ABC_XYZ_Classification!C16 -> Raw Material - Metal Stock | D19: =INDEX(Raw_SKU_Master!$I$2:$I$41,MATCH(A19,Raw_SKU_Master!$A$2:$A$41,0)) -> 57 | E19: =INDEX(Raw_SKU_Master!$E$2:$E$41,MATCH(A19,Raw_SKU_Master!$A$2:$A$41,0)) -> 31.12 | F19: =ABC_XYZ_Classification!E16/(Assumptions!$C$18*7) -> 6.5054945 | G19: =ABC_XYZ_Classification!J16 -> 6.3198757 | H19: =D19/7 -> 8.1428571 | I19: =ROUNDUP(Assumptions!$C$6*G19*SQRT(H19),0) -> 30 | J19: =ROUNDUP(F19*D19+I19,0) -> 401 | K19: =ABC_XYZ_Classification!E16 -> 2368 | L19: =ROUND(SQRT((2*K19*Assumptions!$C$7)/(E19*Assumptions!$C$8)),0) -> 228 | M19: =ROUNDUP(L19/Assumptions!$C$9,0)*Assumptions!$C$9 -> 250 | N19: =AVERAGEIF(Raw_Inventory_Monthly!$A$2:$A$481,A19,Raw_Inventory_Monthly!$C$2:$C$481) -> 61 | O19: =AVERAGEIF(Raw_Inventory_Monthly!$A$2:$A$481,A19,Raw_Inventory_Monthly!$G$2:$G$481) -> 33.5 | P19: =IFERROR(N19/F19,0) -> 9.3766892 | Q19: =IFERROR((N19+O19)/F19,0) -> 14.526182 | R19: =IF(Q19<Assumptions!$C$16*D19,"Stockout Risk",IF(Q19>Assumptions!$C$17*D19,"Overstock","Healthy")) -> Stockout Risk | S19: =ROUND(FORECAST(MAX(Raw_Sales_Weekly!$E$1534:$E$1585)+1,Raw_Sales_Weekly!$C$1534:$C$1585,Raw_Sales_Weekly!$E$1534:$E$1585),0) -> 45 | T19: =ABC_XYZ_Classification!L16 -> X | U19: =ABC_XYZ_Classification!H16 -> A | V19: =IF(AND(P19>$F$5,T19="Z"),"Yes","No") -> No | W19: =N19*E19 -> 1898.32 | X19: =IF(V19="Yes",COUNTIF($V$9:V19,"Yes"),"")
A20: MM-1018 | B20: =ABC_XYZ_Classification!B17 -> Sensors Item 04 - Sensors & Controls | C20: =ABC_XYZ_Classification!C17 -> Sensors & Controls | D20: =INDEX(Raw_SKU_Master!$I$2:$I$41,MATCH(A20,Raw_SKU_Master!$A$2:$A$41,0)) -> 25 | E20: =INDEX(Raw_SKU_Master!$E$2:$E$41,MATCH(A20,Raw_SKU_Master!$A$2:$A$41,0)) -> 4.34 | F20: =ABC_XYZ_Classification!E17/(Assumptions!$C$18*7) -> 25.802198 | G20: =ABC_XYZ_Classification!J17 -> 55.467299 | H20: =D20/7 -> 3.5714286 | I20: =ROUNDUP(Assumptions!$C$6*G20*SQRT(H20),0) -> 173 | J20: =ROUNDUP(F20*D20+I20,0) -> 819 | K20: =ABC_XYZ_Classification!E17 -> 9392 | L20: =ROUND(SQRT((2*K20*Assumptions!$C$7)/(E20*Assumptions!$C$8)),0) -> 1215 | M20: =ROUNDUP(L20/Assumptions!$C$9,0)*Assumptions!$C$9 -> 1225 | N20: =AVERAGEIF(Raw_Inventory_Monthly!$A$2:$A$481,A20,Raw_Inventory_Monthly!$C$2:$C$481) -> 866.16667 | O20: =AVERAGEIF(Raw_Inventory_Monthly!$A$2:$A$481,A20,Raw_Inventory_Monthly!$G$2:$G$481) -> 166.25 | P20: =IFERROR(N20/F20,0) -> 33.569492 | Q20: =IFERROR((N20+O20)/F20,0) -> 40.012741 | R20: =IF(Q20<Assumptions!$C$16*D20,"Stockout Risk",IF(Q20>Assumptions!$C$17*D20,"Overstock","Healthy")) -> Healthy | S20: =ROUND(FORECAST(MAX(Raw_Sales_Weekly!$E$788:$E$839)+1,Raw_Sales_Weekly!$C$788:$C$839,Raw_Sales_Weekly!$E$788:$E$839),0) -> 170 | T20: =ABC_XYZ_Classification!L17 -> Y | U20: =ABC_XYZ_Classification!H17 -> A | V20: =IF(AND(P20>$F$5,T20="Z"),"Yes","No") -> No | W20: =N20*E20 -> 3759.1633 | X20: =IF(V20="Yes",COUNTIF($V$9:V20,"Yes"),"")
A21: MM-1026 | B21: =ABC_XYZ_Classification!B18 -> Pneumatic Components Item 02 - Pneumatic Components | C21: =ABC_XYZ_Classification!C18 -> Pneumatic Components | D21: =INDEX(Raw_SKU_Master!$I$2:$I$41,MATCH(A21,Raw_SKU_Master!$A$2:$A$41,0)) -> 51 | E21: =INDEX(Raw_SKU_Master!$E$2:$E$41,MATCH(A21,Raw_SKU_Master!$A$2:$A$41,0)) -> 12.21 | F21: =ABC_XYZ_Classification!E18/(Assumptions!$C$18*7) -> 9.8653846 | G21: =ABC_XYZ_Classification!J18 -> 24.676689 | H21: =D21/7 -> 7.2857143 | I21: =ROUNDUP(Assumptions!$C$6*G21*SQRT(H21),0) -> 110 | J21: =ROUNDUP(F21*D21+I21,0) -> 614 | K21: =ABC_XYZ_Classification!E18 -> 3591 | L21: =ROUND(SQRT((2*K21*Assumptions!$C$7)/(E21*Assumptions!$C$8)),0) -> 448 | M21: =ROUNDUP(L21/Assumptions!$C$9,0)*Assumptions!$C$9 -> 450 | N21: =AVERAGEIF(Raw_Inventory_Monthly!$A$2:$A$481,A21,Raw_Inventory_Monthly!$C$2:$C$481) -> 430.25 | O21: =AVERAGEIF(Raw_Inventory_Monthly!$A$2:$A$481,A21,Raw_Inventory_Monthly!$G$2:$G$481) -> 61.583333 | P21: =IFERROR(N21/F21,0) -> 43.612086 | Q21: =IFERROR((N21+O21)/F21,0) -> 49.854451 | R21: =IF(Q21<Assumptions!$C$16*D21,"Stockout Risk",IF(Q21>Assumptions!$C$17*D21,"Overstock","Healthy")) -> Stockout Risk | S21: =ROUND(FORECAST(MAX(Raw_Sales_Weekly!$E$1202:$E$1253)+1,Raw_Sales_Weekly!$C$1202:$C$1253,Raw_Sales_Weekly!$E$1202:$E$1253),0) -> 56 | T21: =ABC_XYZ_Classification!L18 -> Y | U21: =ABC_XYZ_Classification!H18 -> A | V21: =IF(AND(P21>$F$5,T21="Z"),"Yes","No") -> No | W21: =N21*E21 -> 5253.3525 | X21: =IF(V21="Yes",COUNTIF($V$9:V21,"Yes"),"")
A22: MM-1009 | B22: =ABC_XYZ_Classification!B19 -> Bearings Item 05 - Bearings & Bushings | C22: =ABC_XYZ_Classification!C19 -> Bearings & Bushings | D22: =INDEX(Raw_SKU_Master!$I$2:$I$41,MATCH(A22,Raw_SKU_Master!$A$2:$A$41,0)) -> 141 | E22: =INDEX(Raw_SKU_Master!$E$2:$E$41,MATCH(A22,Raw_SKU_Master!$A$2:$A$41,0)) -> 5.45 | F22: =ABC_XYZ_Classification!E19/(Assumptions!$C$18*7) -> 25.046703 | G22: =ABC_XYZ_Classification!J19 -> 37.503703 | H22: =D22/7 -> 20.142857 | I22: =ROUNDUP(Assumptions!$C$6*G22*SQRT(H22),0) -> 278 | J22: =ROUNDUP(F22*D22+I22,0) -> 3810 | K22: =ABC_XYZ_Classification!E19 -> 9117 | L22: =ROUND(SQRT((2*K22*Assumptions!$C$7)/(E22*Assumptions!$C$8)),0) -> 1068 | M22: =ROUNDUP(L22/Assumptions!$C$9,0)*Assumptions!$C$9 -> 1075 | N22: =AVERAGEIF(Raw_Inventory_Monthly!$A$2:$A$481,A22,Raw_Inventory_Monthly!$C$2:$C$481) -> 293 | O22: =AVERAGEIF(Raw_Inventory_Monthly!$A$2:$A$481,A22,Raw_Inventory_Monthly!$G$2:$G$481) -> 184.16667 | P22: =IFERROR(N22/F22,0) -> 11.698146 | Q22: =IFERROR((N22+O22)/F22,0) -> 19.051077 | R22: =IF(Q22<Assumptions!$C$16*D22,"Stockout Risk",IF(Q22>Assumptions!$C$17*D22,"Overstock","Healthy")) -> Stockout Risk | S22: =ROUND(FORECAST(MAX(Raw_Sales_Weekly!$E$388:$E$439)+1,Raw_Sales_Weekly!$C$388:$C$439,Raw_Sales_Weekly!$E$388:$E$439),0) -> 151 | T22: =ABC_XYZ_Classification!L19 -> X | U22: =ABC_XYZ_Classification!H19 -> A | V22: =IF(AND(P22>$F$5,T22="Z"),"Yes","No") -> No | W22: =N22*E22 -> 1596.85 | X22: =IF(V22="Yes",COUNTIF($V$9:V22,"Yes"),"")
A23: MM-1012 | B23: =ABC_XYZ_Classification!B20 -> Electric Motors Item 03 - Electric Motors & Drives | C23: =ABC_XYZ_Classification!C20 -> Electric Motors & Drives | D23: =INDEX(Raw_SKU_Master!$I$2:$I$41,MATCH(A23,Raw_SKU_Master!$A$2:$A$41,0)) -> 39 | E23: =INDEX(Raw_SKU_Master!$E$2:$E$41,MATCH(A23,Raw_SKU_Master!$A$2:$A$41,0)) -> 17.6 | F23: =ABC_XYZ_Classification!E20/(Assumptions!$C$18*7) -> 5.8351648 | G23: =ABC_XYZ_Classification!J20 -> 22.763339 | H23: =D23/7 -> 5.5714286 | I23: =ROUNDUP(Assumptions!$C$6*G23*SQRT(H23),0) -> 89 | J23: =ROUNDUP(F23*D23+I23,0) -> 317 | K23: =ABC_XYZ_Classification!E20 -> 2124 | L23: =ROUND(SQRT((2*K23*Assumptions!$C$7)/(E23*Assumptions!$C$8)),0) -> 287 | M23: =ROUNDUP(L23/Assumptions!$C$9,0)*Assumptions!$C$9 -> 300 | N23: =AVERAGEIF(Raw_Inventory_Monthly!$A$2:$A$481,A23,Raw_Inventory_Monthly!$C$2:$C$481) -> 289.66667 | O23: =AVERAGEIF(Raw_Inventory_Monthly!$A$2:$A$481,A23,Raw_Inventory_Monthly!$G$2:$G$481) -> 31.083333 | P23: =IFERROR(N23/F23,0) -> 49.641557 | Q23: =IFERROR((N23+O23)/F23,0) -> 54.968456 | R23: =IF(Q23<Assumptions!$C$16*D23,"Stockout Risk",IF(Q23>Assumptions!$C$17*D23,"Overstock","Healthy")) -> Healthy | S23: =ROUND(FORECAST(MAX(Raw_Sales_Weekly!$E$513:$E$562)+1,Raw_Sales_Weekly!$C$513:$C$562,Raw_Sales_Weekly!$E$513:$E$562),0) -> 31 | T23: =ABC_XYZ_Classification!L20 -> Y | U23: =ABC_XYZ_Classification!H20 -> A | V23: =IF(AND(P23>$F$5,T23="Z"),"Yes","No") -> No | W23: =N23*E23 -> 5098.1333 | X23: =IF(V23="Yes",COUNTIF($V$9:V23,"Yes"),"")
A24: MM-1027 | B24: =ABC_XYZ_Classification!B21 -> Pneumatic Components Item 03 - Pneumatic Components | C24: =ABC_XYZ_Classification!C21 -> Pneumatic Components | D24: =INDEX(Raw_SKU_Master!$I$2:$I$41,MATCH(A24,Raw_SKU_Master!$A$2:$A$41,0)) -> 57 | E24: =INDEX(Raw_SKU_Master!$E$2:$E$41,MATCH(A24,Raw_SKU_Master!$A$2:$A$41,0)) -> 7.11 | F24: =ABC_XYZ_Classification!E21/(Assumptions!$C$18*7) -> 14.82967 | G24: =ABC_XYZ_Classification!J21 -> 63.999501 | H24: =D24/7 -> 8.1428571 | I24: =ROUNDUP(Assumptions!$C$6*G24*SQRT(H24),0) -> 302 | J24: =ROUNDUP(F24*D24+I24,0) -> 1148 | K24: =ABC_XYZ_Classification!E21 -> 5398 | L24: =ROUND(SQRT((2*K24*Assumptions!$C$7)/(E24*Assumptions!$C$8)),0) -> 719 | M24: =ROUNDUP(L24/Assumptions!$C$9,0)*Assumptions!$C$9 -> 725 | N24: =AVERAGEIF(Raw_Inventory_Monthly!$A$2:$A$481,A24,Raw_Inventory_Monthly!$C$2:$C$481) -> 363.91667 | O24: =AVERAGEIF(Raw_Inventory_Monthly!$A$2:$A$481,A24,Raw_Inventory_Monthly!$G$2:$G$481) -> 78.833333 | P24: =IFERROR(N24/F24,0) -> 24.539768 | Q24: =IFERROR((N24+O24)/F24,0) -> 29.855687 | R24: =IF(Q24<Assumptions!$C$16*D24,"Stockout Risk",IF(Q24>Assumptions!$C$17*D24,"Overstock","Healthy")) -> Stockout Risk | S24: =ROUND(FORECAST(MAX(Raw_Sales_Weekly!$E$1254:$E$1304)+1,Raw_Sales_Weekly!$C$1254:$C$1304,Raw_Sales_Weekly!$E$1254:$E$1304),0) -> 117 | T24: =ABC_XYZ_Classification!L21 -> Z | U24: =ABC_XYZ_Classification!H21 -> B | V24: =IF(AND(P24>$F$5,T24="Z"),"Yes","No") -> No | W24: =N24*E24 -> 2587.4475 | X24: =IF(V24="Yes",COUNTIF($V$9:V24,"Yes"),"")
